Workbook

Sheet Total por Atendentes
A1: Atendente | B1: Total Atendimentos
A2: Erika | B2: =_xlfn.XLOOKUP(A2,Pivot!A:A,Pivot!G:G,) -> 204
A3: Marcela | B3: =_xlfn.XLOOKUP(A3,Pivot!A:A,Pivot!G:G,) -> 144
A4: Ana Clara | B4: =_xlfn.XLOOKUP(A4,Pivot!A:A,Pivot!G:G,) -> 138
A5: Anderson | B5: =_xlfn.XLOOKUP(A5,Pivot!A:A,Pivot!G:G,) -> 136
A6: Sarah | B6: =_xlfn.XLOOKUP(A6,Pivot!A:A,Pivot!G:G,) -> 122
A7: Mariana | B7: =_xlfn.XLOOKUP(A7,Pivot!A:A,Pivot!G:G,) -> 113
A8: Fernando | B8: =_xlfn.XLOOKUP(A8,Pivot!A:A,Pivot!G:G,) -> 82
A9: Andreia | B9: =_xlfn.XLOOKUP(A9,Pivot!A:A,Pivot!G:G,) -> 37
A10: Rachel | B10: =_xlfn.XLOOKUP(A10,Pivot!A:A,Pivot!G:G,) -> 14

Sheet Total por Tipo
A1: Tipo de Atendimento | B1: Total
A2: Outros | B2: =_xlfn.XLOOKUP(A2,Pivot!J:J,Pivot!P:P,) -> 150
A3: Informe | B3: =_xlfn.XLOOKUP(A3,Pivot!J:J,Pivot!P:P,) -> 129
A4: Ponto | B4: =_xlfn.XLOOKUP(A4,Pivot!J:J,Pivot!P:P,) -> 82
A5: Férias | B5: =_xlfn.XLOOKUP(A5,Pivot!J:J,Pivot!P:P,) -> 64
A6: VT | B6: =_xlfn.XLOOKUP(A6,Pivot!J:J,Pivot!P:P,) -> 51
A7: Rescisão | B7: =_xlfn.XLOOKUP(A7,Pivot!J:J,Pivot!P:P,) -> 51
A8: Beneficios | B8: =_xlfn.XLOOKUP(A8,Pivot!J:J,Pivot!P:P,) -> 46
A9: Refeição | B9: =_xlfn.XLOOKUP(A9,Pivot!J:J,Pivot!P:P,) -> 43
A10: Folha | B10: =_xlfn.XLOOKUP(A10,Pivot!J:J,Pivot!P:P,) -> 43
A11: Sindical | B11: =_xlfn.XLOOKUP(A11,Pivot!J:J,Pivot!P:P,) -> 37
A12: Afastamento | B12: =_xlfn.XLOOKUP(A12,Pivot!J:J,Pivot!P:P,) -> 37
A13: Declaração | B13: =_xlfn.XLOOKUP(A13,Pivot!J:J,Pivot!P:P,) -> 31
... A34: Creche | B34: =_xlfn.XLOOKUP(A34,Pivot!J:J,Pivot!P:P,) -> 1

Sheet Detalhado
A1: Tipo de Atendimento | B1: Erika | C1: Marcela | D1: Ana Clara | E1: Anderson | F1: Sarah | G1: Mariana | H1: Fernando | I1: Andreia | J1: Rachel
A2: Outros | B2: 27 | C2: 49 | D2: 21 | E2: 11 | F2: 19 | G2: 7 | H2: 13 | I2: 0 | J2: 3
A3: Informe | B3: 1 | C3: 7 | D3: 1 | E3: 47 | F3: 0 | G3: 57 | H3: 16 | I3: 0 | J3: 0
A4: Ponto | B4: 0 | C4: 10 | D4: 7 | E4: 3 | F4: 36 | G4: 0 | H4: 1 | I4: 25 | J4: 0
A5: Férias | B5: 64 | C5: 0 | D5: 0 | E5: 0 | F5: 0 | G5: 0 | H5: 0 | I5: 0 | J5: 0
A6: Rescisão | B6: 3 | C6: 2 | D6: 2 | E6: 0 | F6: 0 | G6: 7 | H6: 36 | I6: 0 | J6: 1
A7: VT | B7: 44 | C7: 0 | D7: 1 | E7: 1 | F7: 5 | G7: 0 | H7: 0 | I7: 0 | J7: 0
A8: Beneficios | B8: 20 | C8: 2 | D8: 20 | E8: 0 | F8: 4 | G8: 0 | H8: 0 | I8: 0 | J8: 0
A9: Folha | B9: 4 | C9: 9 | D9: 0 | E9: 15 | F9: 0 | G9: 0 | H9: 3 | I9: 6 | J9: 6
A10: Refeição | B10: 10 | C10: 5 | D10: 2 | E10: 0 | F10: 16 | G10: 8 | H10: 2 | I10: 0 | J10: 0
A11: Afastamento | B11: 4 | C11: 4 | D11: 11 | E11: 2 | F11: 1 | G11: 10 | H11: 5 | I11: 0 | J11: 0
A12: Sindical | B12: 0 | C12: 2 | D12: 0 | E12: 34 | F12: 0 | G12: 0 | H12: 0 | I12: 0 | J12: 1
A13: Declaração | B13: 2 | C13: 2 | D13: 9 | E13: 0 | F13: 1 | G13: 15 | H13: 0 | I13: 1 | J13: 1
... A17: Consignado | B17: 0 | C17: 15 | D17: 0 | E17: 3 | F17: 0 | G17: 0 | H17: 0 | I17: 1 | J17: 0

Sheet Emails
A1: Data | B1: TimePessoas | C1: Pessoa | D1: RemetenteNome | E1: RemetenteEmail | F1: Assunto | G1: Classificacao
A2: 19/03/2025 10:08:58 | B2: --- Gente e Gestão | D2: Fernanda Goncalves Merguliano | E2: fernanda.merguliano@haoc.com.br | F2: Troca de data de férias - APROVADA | G2: Férias
A3: 06/01/2025 15:28:09 | B3: --- Gente e Gestão | D3: Fernanda Rigueira Barrieli | E3: fernanda.barrieli@haoc.com.br | F3: Cadastro de PJ para criação de e-mail corporativo PROADI-SUS Responsabilidade Social | G3: Outros
A4: 18/02/2025 11:33:39 | B4: --- Gente e Gestão | D4: Ana Laura Batista Zamorel | E4: ana.zamorel@haoc.com.br | F4: Carta oposição ao sindicato de enfermagem | G4: Sindical
A5: 20/02/2025 10:35:38 | B5: --- Gente e Gestão | D5: Milena | E5: milenambs@yahoo.com.br | F5: Carta oposição contribuição sindical | G5: Sindical
A6: 11/02/2025 15:09:06 | B6: --- Gente e Gestão | D6: Sensrit | E6: ssensrit@haoc.com.br | F6: Chamado #R60309 - Inclusão Bolsista Residente - Cálculo Terceiros | G6: Beneficios
A7: 12/02/2025 09:32:42 | B7: --- Gente e Gestão | D7: Sensrit | E7: ssensrit@haoc.com.br | F7: Chamado #R60486 Erro na Geração TXT Dirf 2024/2025 Resolvido | G7: Outros
A8: 19/02/2025 15:45:58 | B8: --- Gente e Gestão | D8: Dulciclea Nunes dos Santos de Araujo | E8: dulciclea.araujo@haoc.com.br | F8: Crachá para terceiros (Acesso ao Hospital) - Medica auditora Care Plus | G8: Crachá
A9: 05/02/2025 15:00:29 | B9: =CONCATENATE("G&G - ",D9) -> G&G - Marcela Avelino Sanchez | C9: =LEFT(D9,FIND(" ",D9)-1) -> Marcela | D9: Marcela Avelino Sanchez | E9: marcela.sanchez@haoc.com.br | F9: RDT - Alteração Pis e Unificação de Contas | G9: RDT
A10: 20/02/2025 10:28:32 | B10: --- Gente e Gestão | D10: Denise Gigli Ferreira | E10: denise.ferreira@haoc.com.br | F10: Vinculo de CNES de colaboradora- Isabela Teixeira Araújo | G10: Outros
A11: 27/03/2025 12:31:28 | B11: --- Gente e Gestão | D11: Marco Matias Rafael | E11: marco.rafael@haoc.com.br | F11: ###### Troca de cobrança de Almoço | G11: Outros
A12: 18/03/2025 10:34:16 | B12: --- Gente e Gestão | D12: Silvano Barbosa | Senior | E12: silvano.barbosa@senior.com.br | F12: #Hacks de Produto – Campos personalizados | G12: Outros
A13: 03/03/2025 09:15:55 | B13: --- Gente e Gestão | D13: Francisco jonatan Da silva sousa | E13: jonatangastronomia30@gmail.com | F13: .informe de rendimentos | G13: Informe
A14: 13/03/2025 09:17:25 | B14: --- Gente e Gestão | D14: Flavia da Metadados | E14: flavianoal@metadados.com.br | F14: [CHECKLIST] O RH no controle: afastamentos sem erros! | G14: Afastamento
A15: 14/03/2025 09:31:17 | B15: --- Gente e Gestão | D15: Flavia da Metadados | E15: flavianoal@metadados.com.br | F15: [EBOOK] Descubra os impactos de afastamentos na folha | G15: Afastamento
A16: 30/01/2025 09:14:04 | B16: --- Gente e Gestão | D16: Flavia da Metadados | E16: flavianoal@metadados.com.br | F16: [GUIA AVANÇADO] Adeus à DIRF sem medo do Leão! | G16: Outros
A17: 06/03/2025 09:20:53 | B17: --- Gente e Gestão | D17: Flavia da Metadados | E17: flavianoal@metadados.com.br | F17: [GUIA] O que o RH precisa saber sobre SST! | G17: Outros
A18: 07/03/2025 16:53:37 | B18: --- | D18: Estevao Bassi | E18: estevao.bassi@haoc.com.br | F18: [Scan] Oposição ao desconto sindicato | G18: Sindical
A19: 07/03/2025 16:53:36 | B19: --- | D19: Estevao Bassi | E19: estevao.bassi@haoc.com.br | F19: [Scan] Oposição ao desconto sindicato | G19: Sindical
A20: 20/01/2025 12:18:08 | B20: --- Gente e Gestão | D20: Renato Garcia | E20: 14607@haoc.com.br | F20: 1_JANEIRO - Rateio time educação | G20: Educa HAOC
A21: 17/01/2025 15:33:57 | B21: --- Gente e Gestão | D21: Jabuticaba Conteúdo | E21: jabuticaba@jabuticabaconteudo.com.br | F21: 10 tendências em vídeo para 2025 | G21: Outros
... A31: 24/02/2025 08:07:28 | B31: --- Gente e Gestão | D31: Isaura Mochnacz | E31: isaura.mochnacz@haoc.com.br | F31: 2° via da carta de oposição de desconto do sindicato | G31: Sindical
A32: 18/03/2025 14:48:55 | B32: =CONCATENATE("G&G - ",D32) -> G&G - Ana Clara Bonifacio da Silva Antonio | C32: Ana Clara | D32: Ana Clara Bonifacio da Silva Antonio | E32: ana.clara@haoc.com.br | F32: 2° VIA DE CRACHÁ | G32: Crachá
A33: 14/02/2025 09:23:56 | B33: =CONCATENATE("G&G - ",D33) -> G&G - Ana Clara Bonifacio da Silva Antonio | C33: Ana Clara | D33: Ana Clara Bonifacio da Silva Antonio | E33: ana.clara@haoc.com.br | F33: 2° VIA DE CRACHÁS | G33: Crachá
A34: 07/03/2025 11:13:02 | B34: --- Gente e Gestão | D34: Manu da D4Sign | E34: marketing@d4signmail.com | F34: 3 dicas rápidas para seu cliente não escolher o concorrente | G34: Outros
A35: 18/02/2025 18:05:40 | B35: --- Gente e Gestão | D35: Rafaela Coimbra de Moraes Silva | E35: rafaela.silva@haoc.com.br | F35: 60.726.502/0001-26 - Recebimentos FGTS Trabalhador R$ 8.324,11 e R$ 16.741,48 - 07/02/2025 | G35: Informe
A36: 10/01/2025 08:45:17 | B36: --- Gente e Gestão | D36: Jabuticaba Conteúdo | E36: jabuticaba@jabuticabaconteudo.com.br | F36: 8 tendências da comunicação para ESG em 2025 | G36: Outros
A37: 15/03/2025 10:00:43 | B37: --- Gente e Gestão | D37: jmarcelobarreto@bol.com.br | E37: jmarcelobarreto@bol.com.br | F37: 8341 abono refeição | G37: Refeição
A38: 18/02/2025 15:31:35 | B38: --- Gente e Gestão | D38: Mariana Prado | NATCORP | E38: mariana.prado@natcorp.com.br | F38: A geração Z chegou à liderança… | G38: Outros
A39: 25/02/2025 09:56:31 | B39: --- Gente e Gestão | D39: Manu da D4Sign | E39: marketing@d4signmail.com | F39: A IA do Google resume textos, o D4Sign.AI revoluciona a gestão de contratos | G39: Outros
A40: 26/03/2025 16:03:44 | B40: --- Gente e Gestão | D40: Jabuticaba Conteúdo | E40: jabuticaba@jabuticabaconteudo.com.br | F40: A Jabuticaba Conteúdo estará nesta sexta no Fórum Abracom 2025 | G40: Outros
A41: 28/02/2025 09:30:41 | B41: --- Gente e Gestão | D41: Marketing | E41: marketing@senior.com.br | F41: A Senior está na Intermodal 2025! 🚀 | G41: Estágio
A42: 04/02/2025 10:07:32 | B42: --- Gente e Gestão | D42: Weliton Rodrigo Ramalho | E42: welitonpaulista31@gmail.com | F42: A/C Sara, liberação de acesso estacionamento | G42: Estacionamento
A43: 24/03/2025 16:29:11 | B43: --- Gente e Gestão | D43: Priscilla Rodrigues de Mello | E43: priscilla.mello@haoc.com.br | F43: Abertura de Agenda Dr Henrique Aprobato | G43: Outros
A44: 20/03/2025 16:39:07 | B44: --- Gente e Gestão | D44: Priscilla Rodrigues de Mello | E44: priscilla.mello@haoc.com.br | F44: Abertura de Agenda Dra Talita Risseto Joaquim Madueno | G44: Outros
A45: 13/01/2025 14:06:37 | B45: =CONCATENATE("G&G - ",D45) -> G&G - Ana Clara Bonifacio da Silva Antonio | C45: Ana Clara | D45: Ana Clara Bonifacio da Silva Antonio | E45: ana.clara@haoc.com.br | F45: Abertura de Conta | G45: Conta Corrente
A46: 21/01/2025 16:17:05 | B46: --- Gente e Gestão | D46: Claudia Maiara Figueiredo Silva | E46: claudia.silva@haoc.com.br | F46: ABONO DO DIA COLABORADOR NPC | G46: Outros
A47: 23/01/2025 16:10:59 | B47: --- Gente e Gestão | D47: Natania Cassia da Conceicao Freitas | E47: desconhecido@desconhecido.com | F47: Aceita: Afastamento Retroativo - Tipo 4 - Acidente Trabalho | G47: Afastamento
A48: 08/01/2025 08:51:48 | B48: =CONCATENATE("G&G - ",D48) -> G&G - Marcela Avelino Sanchez | C48: =LEFT(D48,FIND(" ",D48)-1) -> Marcela | D48: Marcela Avelino Sanchez | E48: desconhecido@desconhecido.com | F48: Aceita: Impacto de ajuste de afastamentos na folha | G48: Afastamento
A49: 08/01/2025 09:20:54 | B49: --- | D49: Erika Felix de Lima | E49: desconhecido@desconhecido.com | F49: Aceita: Impacto de ajuste de afastamentos na folha | G49: Afastamento
...

Sheet Pivot
A3: Nome G&G | B3: TimePessoas | C3: RemetenteEmail | D3: Assunto | E3: RemetenteNome | F3: Data | G3: QTD | J3: Nome G&G | K3: Pessoa | L3: RemetenteEmail | M3: Assunto | N3: RemetenteNome | O3: Data | P3: QTD | S3: QTD | T3: Rótulos de Coluna | AO3: 863
A4: Ana Clara | B4: G&G - Ana Clara Bonifacio da Silva Antonio | G4: 138 | J4: Admissão | P4: 15 | S4: Nome G&G | T4: Ana Clara | U4: Anderson | V4: Andreia | W4: Erika | X4: Fernando | Y4: Marcela | Z4: Mariana | AA4: Rachel | AB4: Sarah | AC4: Total Geral | AF4: =SUBTOTAL(9,AF6:AF38) -> 204 | AG4: =SUBTOTAL(9,AG6:AG38) -> 144 | AH4: =SUBTOTAL(9,AH6:AH38) -> 138 | AI4: =SUBTOTAL(9,AI6:AI38) -> 136 | AJ4: =SUBTOTAL(9,AJ6:AJ38) -> 122 | AK4: =SUBTOTAL(9,AK6:AK38) -> 113 | AL4: =SUBTOTAL(9,AL6:AL38) -> 82 | AM4: =SUBTOTAL(9,AM6:AM38) -> 37 | ... AO4: =SUBTOTAL(9,AO6:AO38) -> 990 | AP4: =AO3/AO4 -> 0.87171717
B5: Admissão | G5: 13 | J5: Adto Cl | P5: 26 | S5: Admissão | T5: 13 | U5: 0 | V5: 0 | W5: 0 | X5: 0 | Y5: 2 | Z5: 0 | AA5: 0 | AB5: 0 | AC5: 15 | AE5: Nome G&G | AF5: Erika | AG5: Marcela | AH5: Ana Clara | AI5: Anderson | AJ5: Sarah | AK5: Mariana | AL5: Fernando | AM5: Andreia | AN5: Rachel | AO5: Total Geral
B6: Afastamento | G6: 11 | J6: Afastamento | P6: 37 | S6: Adto Cl | T6: 0 | U6: 8 | V6: 0 | W6: 1 | X6: 0 | Y6: 16 | Z6: 0 | AA6: 0 | AB6: 1 | AC6: 26 | AE6: Outros | AF6: 27 | AG6: 49 | AH6: 21 | AI6: 11 | AJ6: 19 | AK6: 7 | AL6: 13 | AM6: 0 | AN6: 3 | AO6: 150
B7: Beneficios | G7: 20 | J7: Aposentados | P7: 7 | S7: Afastamento | T7: 11 | U7: 2 | V7: 0 | W7: 4 | X7: 5 | Y7: 4 | Z7: 10 | AA7: 0 | AB7: 1 | AC7: 37 | AE7: Informe | AF7: 1 | AG7: 7 | AH7: 1 | AI7: 47 | AJ7: 0 | AK7: 57 | AL7: 16 | AM7: 0 | AN7: 0 | AO7: 129
B8: Conta Corrente | G8: 8 | J8: Beneficios | P8: 46 | S8: Aposentados | T8: 0 | U8: 0 | V8: 0 | W8: 0 | X8: 3 | Y8: 1 | Z8: 0 | AA8: 0 | AB8: 3 | AC8: 7 | AE8: Ponto | AF8: 0 | AG8: 10 | AH8: 7 | AI8: 3 | AJ8: 36 | AK8: 0 | AL8: 1 | AM8: 25 | AN8: 0 | AO8: 82
B9: Crachá | G9: 19 | J9: Certificado | P9: 2 | S9: Beneficios | T9: 20 | U9: 0 | V9: 0 | W9: 20 | X9: 0 | Y9: 2 | Z9: 0 | AA9: 0 | AB9: 4 | AC9: 46 | AE9: Férias | AF9: 64 | AG9: 0 | AH9: 0 | AI9: 0 | AJ9: 0 | AK9: 0 | AL9: 0 | AM9: 0 | AN9: 0 | AO9: 64
B10: Creche | G10: 1 | J10: Consignado | P10: 19 | S10: Certificado | T10: 0 | U10: 0 | V10: 0 | W10: 2 | X10: 0 | Y10: 0 | Z10: 0 | AA10: 0 | AB10: 0 | AC10: 2 | AE10: Rescisão | AF10: 3 | AG10: 2 | AH10: 2 | AI10: 0 | AJ10: 0 | AK10: 7 | AL10: 36 | AM10: 0 | AN10: 1 | AO10: 51
B11: Declaração | G11: 9 | J11: Conta Corrente | P11: 8 | S11: Consignado | T11: 0 | U11: 3 | V11: 1 | W11: 0 | X11: 0 | Y11: 15 | Z11: 0 | AA11: 0 | AB11: 0 | AC11: 19 | AE11: VT | AF11: 44 | AG11: 0 | AH11: 1 | AI11: 1 | AJ11: 5 | AK11: 0 | AL11: 0 | AM11: 0 | AN11: 0 | AO11: 51
B12: Educa HAOC | G12: 4 | J12: Crachá | P12: 28 | S12: Conta Corrente | T12: 8 | U12: 0 | V12: 0 | W12: 0 | X12: 0 | Y12: 0 | Z12: 0 | AA12: 0 | AB12: 0 | AC12: 8 | AE12: Beneficios | AF12: 20 | AG12: 2 | AH12: 20 | AI12: 0 | AJ12: 4 | AK12: 0 | AL12: 0 | AM12: 0 | AN12: 0 | AO12: 46
B13: Estacionamento | G13: 2 | J13: Creche | P13: 1 | S13: Crachá | T13: 19 | U13: 0 | V13: 0 | W13: 2 | X13: 0 | Y13: 0 | Z13: 2 | AA13: 0 | AB13: 5 | AC13: 28 | AE13: Folha | AF13: 4 | AG13: 9 | AH13: 0 | AI13: 15 | AJ13: 0 | AK13: 0 | AL13: 3 | AM13: 6 | AN13: 6 | AO13: 43
B14: Estágio | G14: 7 | J14: Declaração | P14: 31 | S14: Creche | T14: 1 | U14: 0 | V14: 0 | W14: 0 | X14: 0 | Y14: 0 | Z14: 0 | AA14: 0 | AB14: 0 | AC14: 1 | AE14: Refeição | AF14: 10 | AG14: 5 | AH14: 2 | AI14: 0 | AJ14: 16 | AK14: 8 | AL14: 2 | AM14: 0 | AN14: 0 | AO14: 43
B15: Holerite | G15: 3 | J15: Drogaria | P15: 3 | S15: Declaração | T15: 9 | U15: 0 | V15: 1 | W15: 2 | X15: 0 | Y15: 2 | Z15: 15 | AA15: 1 | AB15: 1 | AC15: 31 | AE15: Afastamento | AF15: 4 | AG15: 4 | AH15: 11 | AI15: 2 | AJ15: 1 | AK15: 10 | AL15: 5 | AM15: 0 | AN15: 0 | AO15: 37
B16: Informe | G16: 1 | J16: Educa HAOC | P16: 13 | S16: Drogaria | T16: 0 | U16: 0 | V16: 0 | W16: 1 | X16: 0 | Y16: 1 | Z16: 0 | AA16: 0 | AB16: 1 | AC16: 3 | AE16: Sindical | AF16: 0 | AG16: 2 | AH16: 0 | AI16: 34 | AJ16: 0 | AK16: 0 | AL16: 0 | AM16: 0 | AN16: 1 | AO16: 37
B17: Maternidade | G17: 7 | J17: Estacionamento | P17: 26 | S17: Educa HAOC | T17: 4 | U17: 0 | V17: 1 | W17: 4 | X17: 0 | Y17: 3 | Z17: 1 | AA17: 0 | AB17: 0 | AC17: 13 | AE17: Declaração | AF17: 2 | AG17: 2 | AH17: 9 | AI17: 0 | AJ17: 1 | AK17: 15 | AL17: 0 | AM17: 1 | AN17: 1 | AO17: 31
... B22: VT | G22: 1 | J22: Informe | P22: 129 | S22: Holerite | T22: 3 | U22: 3 | V22: 0 | W22: 0 | X22: 0 | Y22: 1 | Z22: 3 | AA22: 0 | AB22: 0 | AC22: 10 | AE22: Estágio | AF22: 1 | AG22: 5 | AH22: 7 | AI22: 0 | AJ22: 5 | AK22: 0 | AL22: 0 | AM22: 0 | AN22: 0 | AO22: 18
A23: Anderson | B23: G&G - Anderson Marinho de Souza | G23: 136 | J23: INSS | P23: 8 | S23: Informe | T23: 1 | U23: 47 | V23: 0 | W23: 1 | X23: 16 | Y23: 7 | Z23: 57 | AA23: 0 | AB23: 0 | AC23: 129 | AE23: Admissão | AF23: 0 | AG23: 2 | AH23: 13 | AI23: 0 | AJ23: 0 | AK23: 0 | AL23: 0 | AM23: 0 | AN23: 0 | AO23: 15
B24: Adto Cl | G24: 8 | J24: Maternidade | P24: 8 | S24: INSS | T24: 0 | U24: 6 | V24: 0 | W24: 0 | X24: 1 | Y24: 1 | Z24: 0 | AA24: 0 | AB24: 0 | AC24: 8 | AE24: Educa HAOC | AF24: 4 | AG24: 3 | AH24: 4 | AI24: 0 | AJ24: 0 | AK24: 1 | AL24: 0 | AM24: 1 | AN24: 0 | AO24: 13
B25: Afastamento | G25: 2 | J25: Outros | P25: 150 | S25: Maternidade | T25: 7 | U25: 0 | V25: 0 | W25: 0 | X25: 1 | Y25: 0 | Z25: 0 | AA25: 0 | AB25: 0 | AC25: 8 | AE25: Holerite | AF25: 0 | AG25: 1 | AH25: 3 | AI25: 3 | AJ25: 0 | AK25: 3 | AL25: 0 | AM25: 0 | AN25: 0 | AO25: 10
B26: Consignado | G26: 3 | J26: Pensão | P26: 2 | S26: Outros | T26: 21 | U26: 11 | V26: 0 | W26: 27 | X26: 13 | Y26: 49 | Z26: 7 | AA26: 3 | AB26: 19 | AC26: 150 | AE26: Conta Corrente | AF26: 0 | AG26: 0 | AH26: 8 | AI26: 0 | AJ26: 0 | AK26: 0 | AL26: 0 | AM26: 0 | AN26: 0 | AO26: 8
B27: Folha | G27: 15 | J27: Ponto | P27: 82 | S27: Pensão | T27: 0 | U27: 0 | V27: 0 | W27: 0 | X27: 0 | Y27: 0 | Z27: 0 | AA27: 2 | AB27: 0 | AC27: 2 | AE27: INSS | AF27: 0 | AG27: 1 | AH27: 0 | AI27: 6 | AJ27: 0 | AK27: 0 | AL27: 1 | AM27: 0 | AN27: 0 | AO27: 8
B28: Holerite | G28: 3 | J28: PPP | P28: 5 | S28: Ponto | T28: 7 | U28: 3 | V28: 25 | W28: 0 | X28: 1 | Y28: 10 | Z28: 0 | AA28: 0 | AB28: 36 | AC28: 82 | AE28: Maternidade | AF28: 0 | AG28: 0 | AH28: 7 | AI28: 0 | AJ28: 0 | AK28: 0 | AL28: 1 | AM28: 0 | AN28: 0 | AO28: 8
B29: Informe | G29: 47 | J29: Propor | P29: 6 | S29: PPP | T29: 0 | U29: 0 | V29: 0 | W29: 3 | X29: 0 | Y29: 2 | Z29: 0 | AA29: 0 | AB29: 0 | AC29: 5 | AE29: RDT | AF29: 0 | AG29: 4 | AH29: 0 | AI29: 2 | AJ29: 1 | AK29: 0 | AL29: 1 | AM29: 0 | AN29: 0 | AO29: 8
B30: INSS | G30: 6 | J30: RDT | P30: 8 | S30: Propor | T30: 0 | U30: 1 | V30: 0 | W30: 1 | X30: 0 | Y30: 1 | Z30: 3 | AA30: 0 | AB30: 0 | AC30: 6 | AE30: SV | AF30: 4 | AG30: 0 | AH30: 0 | AI30: 0 | AJ30: 4 | AK30: 0 | AL30: 0 | AM30: 0 | AN30: 0 | AO30: 8
B31: Outros | G31: 11 | J31: Refeição | P31: 43 | S31: RDT | T31: 0 | U31: 2 | V31: 0 | W31: 0 | X31: 1 | Y31: 4 | Z31: 0 | AA31: 0 | AB31: 1 | AC31: 8 | AE31: Aposentados | AF31: 0 | AG31: 1 | AH31: 0 | AI31: 0 | AJ31: 3 | AK31: 0 | AL31: 3 | AM31: 0 | AN31: 0 | AO31: 7
B32: Ponto | G32: 3 | J32: Rescisão | P32: 51 | S32: Refeição | T32: 2 | U32: 0 | V32: 0 | W32: 10 | X32: 2 | Y32: 5 | Z32: 8 | AA32: 0 | AB32: 16 | AC32: 43 | AE32: Propor | AF32: 1 | AG32: 1 | AH32: 0 | AI32: 1 | AJ32: 0 | AK32: 3 | AL32: 0 | AM32: 0 | AN32: 0 | AO32: 6
B33: Propor | G33: 1 | J33: Sindical | P33: 37 | S33: Rescisão | T33: 2 | U33: 0 | V33: 0 | W33: 3 | X33: 36 | Y33: 2 | Z33: 7 | AA33: 1 | AB33: 0 | AC33: 51 | AE33: PPP | AF33: 3 | AG33: 2 | AH33: 0 | AI33: 0 | AJ33: 0 | AK33: 0 | AL33: 0 | AM33: 0 | AN33: 0 | AO33: 5
B34: RDT | G34: 2 | J34: SV | P34: 8 | S34: Sindical | T34: 0 | U34: 34 | V34: 0 | W34: 0 | X34: 0 | Y34: 2 | Z34: 0 | AA34: 1 | AB34: 0 | AC34: 37 | AE34: Universe | AF34: 5 | AG34: 0 | AH34: 0 | AI34: 0 | AJ34: 0 | AK34: 0 | AL34: 0 | AM34: 0 | AN34: 0 | AO34: 5
B35: Sindical | G35: 34 | J35: Universe | P35: 5 | S35: SV | T35: 0 | U35: 0 | V35: 0 | W35: 4 | X35: 0 | Y35: 0 | Z35: 0 | AA35: 0 | AB35: 4 | AC35: 8 | AE35: Drogaria | AF35: 1 | AG35: 1 | AH35: 0 | AI35: 0 | AJ35: 1 | AK35: 0 | AL35: 0 | AM35: 0 | AN35: 0 | AO35: 3
B36: VT | G36: 1 | J36: VT | P36: 51 | S36: Universe | T36: 0 | U36: 0 | V36: 0 | W36: 5 | X36: 0 | Y36: 0 | Z36: 0 | AA36: 0 | AB36: 0 | AC36: 5 | AE36: Certificado | AF36: 2 | AG36: 0 | AH36: 0 | AI36: 0 | AJ36: 0 | AK36: 0 | AL36: 0 | AM36: 0 | AN36: 0 | AO36: 2
A37: Andreia | B37: G&G - Andreia Cristina Tomaz Mataruco | G37: 37 | J37: Total Geral | P37: 990 | S37: VT | T37: 1 | U37: 1 | V37: 0 | W37: 44 | X37: 0 | Y37: 0 | Z37: 0 | AA37: 0 | AB37: 5 | AC37: 51 | AE37: Pensão | AF37: 0 | AG37: 0 | AH37: 0 | AI37: 0 | AJ37: 0 | AK37: 0 | AL37: 0 | AM37: 0 | AN37: 2 | AO37: 2
B38: Consignado | G38: 1 | S38: Total Geral | T38: 138 | U38: 136 | V38: 37 | W38: 204 | X38: 82 | Y38: 144 | Z38: 113 | AA38: 14 | AB38: 122 | AC38: 990 | AE38: Creche | AF38: 0 | AG38: 0 | AH38: 1 | AI38: 0 | AJ38: 0 | AK38: 0 | AL38: 0 | AM38: 0 | AN38: 0 | AO38: 1
B39: Declaração | G39: 1
B40: Educa HAOC | G40: 1
B41: Estacionamento | G41: 3
B42: Folha | G42: 6
B43: Ponto | G43: 25
A44: Erika | B44: G&G - Erika Felix de Lima | G44: 204
B45: Adto Cl | G45: 1
B46: Afastamento | G46: 4
...
